Workbook

Sheet Dashboard
B2: Panel de seguimiento del Plan de Igualdad Interno
B3: Se actualiza automáticamente a medida que se rellena la hoja de Seguimiento.
B5: ESTADO DE LAS ACCIONES | I5: AVANCE POR EJE (acciones ejecutadas algún año)
B6: Estado | C6: 2027 | D6: 2028 | E6: 2029 | F6: 2030 | I6: Eje | J6: Total acc. | K6: Ejecutadas | L6: %
B7: Ejecutada | C7: =COUNTIF(Seguimiento!$G$5:$G$64,"Ejecutada") -> 3 | D7: =COUNTIF(Seguimiento!$M$5:$M$64,"Ejecutada") -> 0 | E7: =COUNTIF(Seguimiento!$S$5:$S$64,"Ejecutada") -> 0 | F7: =COUNTIF(Seguimiento!$Y$5:$Y$64,"Ejecutada") -> 0 | I7: 1. Gestión de personas | J7: =COUNTIF(Seguimiento!$B$5:$B$64,1) -> 9 | K7: =SUMPRODUCT((Seguimiento!$B$5:$B$64=1)*(((Seguimiento!$G$5:$G$64="Ejecutada")+(Seguimiento!$M$5:$M$64="Ejecutada")+(Seguimiento!$S$5:$S$64="Ejecutada")+(Seguimiento!$Y$5:$Y$64="Ejecutada"))>0)) -> 3 | L7: =IFERROR(K7/J7,0) -> 0.33333333
B8: En curso | C8: =COUNTIF(Seguimiento!$G$5:$G$64,"En curso") -> 0 | D8: =COUNTIF(Seguimiento!$M$5:$M$64,"En curso") -> 0 | E8: =COUNTIF(Seguimiento!$S$5:$S$64,"En curso") -> 0 | F8: =COUNTIF(Seguimiento!$Y$5:$Y$64,"En curso") -> 0 | I8: 2. Acceso y selección | J8: =COUNTIF(Seguimiento!$B$5:$B$64,2) -> 9 | K8: =SUMPRODUCT((Seguimiento!$B$5:$B$64=2)*(((Seguimiento!$G$5:$G$64="Ejecutada")+(Seguimiento!$M$5:$M$64="Ejecutada")+(Seguimiento!$S$5:$S$64="Ejecutada")+(Seguimiento!$Y$5:$Y$64="Ejecutada"))>0)) -> 0 | L8: =IFERROR(K8/J8,0) -> 0
B9: No iniciada | C9: =COUNTIF(Seguimiento!$G$5:$G$64,"No iniciada") -> 0 | D9: =COUNTIF(Seguimiento!$M$5:$M$64,"No iniciada") -> 0 | E9: =COUNTIF(Seguimiento!$S$5:$S$64,"No iniciada") -> 0 | F9: =COUNTIF(Seguimiento!$Y$5:$Y$64,"No iniciada") -> 0 | I9: 3. Formación | J9: =COUNTIF(Seguimiento!$B$5:$B$64,3) -> 10 | K9: =SUMPRODUCT((Seguimiento!$B$5:$B$64=3)*(((Seguimiento!$G$5:$G$64="Ejecutada")+(Seguimiento!$M$5:$M$64="Ejecutada")+(Seguimiento!$S$5:$S$64="Ejecutada")+(Seguimiento!$Y$5:$Y$64="Ejecutada"))>0)) -> 0 | L9: =IFERROR(K9/J9,0) -> 0
B10: Aplazada | C10: =COUNTIF(Seguimiento!$G$5:$G$64,"Aplazada") -> 0 | D10: =COUNTIF(Seguimiento!$M$5:$M$64,"Aplazada") -> 0 | E10: =COUNTIF(Seguimiento!$S$5:$S$64,"Aplazada") -> 0 | F10: =COUNTIF(Seguimiento!$Y$5:$Y$64,"Aplazada") -> 0 | I10: 4. Seguridad y salud | J10: =COUNTIF(Seguimiento!$B$5:$B$64,4) -> 7 | K10: =SUMPRODUCT((Seguimiento!$B$5:$B$64=4)*(((Seguimiento!$G$5:$G$64="Ejecutada")+(Seguimiento!$M$5:$M$64="Ejecutada")+(Seguimiento!$S$5:$S$64="Ejecutada")+(Seguimiento!$Y$5:$Y$64="Ejecutada"))>0)) -> 0 | L10: =IFERROR(K10/J10,0) -> 0
B11: No procede | C11: =COUNTIF(Seguimiento!$G$5:$G$64,"No procede") -> 0 | D11: =COUNTIF(Seguimiento!$M$5:$M$64,"No procede") -> 0 | E11: =COUNTIF(Seguimiento!$S$5:$S$64,"No procede") -> 0 | F11: =COUNTIF(Seguimiento!$Y$5:$Y$64,"No procede") -> 0 | I11: 5. Valoración y retribución | J11: =COUNTIF(Seguimiento!$B$5:$B$64,5) -> 7 | K11: =SUMPRODUCT((Seguimiento!$B$5:$B$64=5)*(((Seguimiento!$G$5:$G$64="Ejecutada")+(Seguimiento!$M$5:$M$64="Ejecutada")+(Seguimiento!$S$5:$S$64="Ejecutada")+(Seguimiento!$Y$5:$Y$64="Ejecutada"))>0)) -> 0 | L11: =IFERROR(K11/J11,0) -> 0
B12: Total con seguimiento | C12: =SUM(C7:C11) -> 3 | D12: =SUM(D7:D11) -> 0 | E12: =SUM(E7:E11) -> 0 | F12: =SUM(F7:F11) -> 0 | I12: 6. Conciliación | J12: =COUNTIF(Seguimiento!$B$5:$B$64,6) -> 6 | K12: =SUMPRODUCT((Seguimiento!$B$5:$B$64=6)*(((Seguimiento!$G$5:$G$64="Ejecutada")+(Seguimiento!$M$5:$M$64="Ejecutada")+(Seguimiento!$S$5:$S$64="Ejecutada")+(Seguimiento!$Y$5:$Y$64="Ejecutada"))>0)) -> 0 | L12: =IFERROR(K12/J12,0) -> 0
I13: 7. Cultura organizacional | J13: =COUNTIF(Seguimiento!$B$5:$B$64,7) -> 6 | K13: =SUMPRODUCT((Seguimiento!$B$5:$B$64=7)*(((Seguimiento!$G$5:$G$64="Ejecutada")+(Seguimiento!$M$5:$M$64="Ejecutada")+(Seguimiento!$S$5:$S$64="Ejecutada")+(Seguimiento!$Y$5:$Y$64="Ejecutada"))>0)) -> 0 | L13: =IFERROR(K13/J13,0) -> 0
B14: GRADO DE AVANCE | I14: 8. Violencia y acoso | J14: =COUNTIF(Seguimiento!$B$5:$B$64,8) -> 6 | K14: =SUMPRODUCT((Seguimiento!$B$5:$B$64=8)*(((Seguimiento!$G$5:$G$64="Ejecutada")+(Seguimiento!$M$5:$M$64="Ejecutada")+(Seguimiento!$S$5:$S$64="Ejecutada")+(Seguimiento!$Y$5:$Y$64="Ejecutada"))>0)) -> 0 | L14: =IFERROR(K14/J14,0) -> 0
B15: Indicador | C15: 2027 | D15: 2028 | E15: 2029 | F15: 2030
B16: Acciones previstas | C16: =COUNTIF(Seguimiento!$D$5:$D$64,"*2027*")+COUNTIF(Seguimiento!$D$5:$D$64,"Todos los años") -> 34 | D16: =COUNTIF(Seguimiento!$D$5:$D$64,"*2028*")+COUNTIF(Seguimiento!$D$5:$D$64,"Todos los años") -> 31 | E16: =COUNTIF(Seguimiento!$D$5:$D$64,"*2029*")+COUNTIF(Seguimiento!$D$5:$D$64,"Todos los años") -> 29 | F16: =COUNTIF(Seguimiento!$D$5:$D$64,"*2030*")+COUNTIF(Seguimiento!$D$5:$D$64,"Todos los años") -> 23
B17: Ejecutadas | C17: =COUNTIF(Seguimiento!$G$5:$G$64,"Ejecutada") -> 3 | D17: =COUNTIF(Seguimiento!$M$5:$M$64,"Ejecutada") -> 0 | E17: =COUNTIF(Seguimiento!$S$5:$S$64,"Ejecutada") -> 0 | F17: =COUNTIF(Seguimiento!$Y$5:$Y$64,"Ejecutada") -> 0
B18: % ejecución | C18: =IFERROR(C17/C16,0) -> 0.088235294 | D18: =IFERROR(D17/D16,0) -> 0 | E18: =IFERROR(E17/E16,0) -> 0 | F18: =IFERROR(F17/F16,0) -> 0
B21: EJECUCIÓN: PREVISTO vs EJECUTADO
C22: 2027 | D22: 2028 | E22: 2029 | F22: 2030 | G22: Total
B23: Horas previstas | C23: =Resumen!C9 -> 788 | D23: =Resumen!D9 -> 830 | E23: =Resumen!E9 -> 708 | F23: =Resumen!F9 -> 700 | G23: =SUM(C23:F23) -> 3026
B24: Horas ejecutadas | C24: =SUM(Seguimiento!$J$5:$J$64) -> 60 | D24: =SUM(Seguimiento!$P$5:$P$64) -> 0 | E24: =SUM(Seguimiento!$V$5:$V$64) -> 0 | F24: =SUM(Seguimiento!$AB$5:$AB$64) -> 0 | G24: =SUM(C24:F24) -> 60
B25: Ppto previsto (€) | C25: =Resumen!C18 -> 24500 | D25: =Resumen!D18 -> 16300 | E25: =Resumen!E18 -> 11100 | F25: =Resumen!F18 -> 6600 | G25: =SUM(C25:F25) -> 58500
B26: Ppto ejecutado (€) | C26: =SUM(Seguimiento!$K$5:$K$64) -> 1500 | D26: =SUM(Seguimiento!$Q$5:$Q$64) -> 0 | E26: =SUM(Seguimiento!$W$5:$W$64) -> 0 | F26: =SUM(Seguimiento!$AC$5:$AC$64) -> 0 | G26: =SUM(C26:F26) -> 1500

Sheet Resumen
B2: Plan de Igualdad Interno · Ayuntamiento de Ortuella
B3: Resumen operativo y económico del plan (2027-2030)
B5: HORAS DE GESTIÓN POR AÑO
C6: 2027 | D6: 2028 | E6: 2029 | F6: 2030 | G6: TOTAL
B7: Persona responsable de la gestión del plan, dependiente de Secretaría | C7: =SUM('Datos (aux)'!D2:D61) -> 648 | D7: =SUM('Datos (aux)'!E2:E61) -> 644 | E7: =SUM('Datos (aux)'!F2:F61) -> 612 | F7: =SUM('Datos (aux)'!G2:G61) -> 600 | G7: =SUM(C7:F7) -> 2504
B8: Apoyos (Secretaría, técnica, otros) | C8: =SUM('Datos (aux)'!H2:H61) -> 140 | D8: =SUM('Datos (aux)'!I2:I61) -> 186 | E8: =SUM('Datos (aux)'!J2:J61) -> 96 | F8: =SUM('Datos (aux)'!K2:K61) -> 100 | G8: =SUM(C8:F8) -> 522
B9: TOTAL horas de gestión | C9: =SUM(C7:C8) -> 788 | D9: =SUM(D7:D8) -> 830 | E9: =SUM(E7:E8) -> 708 | F9: =SUM(F7:F8) -> 700 | G9: =SUM(C9:F9) -> 3026
B11: La dedicación de gestión se cubre con la persona contratada anualmente a través del plan de empleo (con
B12: formación en igualdad) y el apoyo del personal municipal. Las horas son estimativas y orientan la planificación.
B14: PRESUPUESTO DE EXTERNALIZACIÓN
C15: 2027 | D15: 2028 | E15: 2029 | F15: 2030 | G15: TOTAL
B16: Instrumentos globales (*) | C16: =SUMIFS('Datos (aux)'!L2:L61,'Datos (aux)'!$B$2:$B$61,"Instrumento global") -> 21500 | D16: =SUMIFS('Datos (aux)'!M2:M61,'Datos (aux)'!$B$2:$B$61,"Instrumento global") -> 0 | E16: =SUMIFS('Datos (aux)'!N2:N61,'Datos (aux)'!$B$2:$B$61,"Instrumento global") -> 5000 | F16: =SUMIFS('Datos (aux)'!O2:O61,'Datos (aux)'!$B$2:$B$61,"Instrumento global") -> 0 | G16: =SUM(C16:F16) -> 26500
B17: Propio del plan de igualdad | C17: =SUMIFS('Datos (aux)'!L2:L61,'Datos (aux)'!$B$2:$B$61,"Propio del plan") -> 3000 | D17: =SUMIFS('Datos (aux)'!M2:M61,'Datos (aux)'!$B$2:$B$61,"Propio del plan") -> 16300 | E17: =SUMIFS('Datos (aux)'!N2:N61,'Datos (aux)'!$B$2:$B$61,"Propio del plan") -> 6100 | F17: =SUMIFS('Datos (aux)'!O2:O61,'Datos (aux)'!$B$2:$B$61,"Propio del plan") -> 6600 | G17: =SUM(C17:F17) -> 32000
B18: TOTAL externalización | C18: =SUM(C16:C17) -> 24500 | D18: =SUM(D16:D17) -> 16300 | E18: =SUM(E16:E17) -> 11100 | F18: =SUM(F16:F17) -> 6600 | G18: =SUM(C18:F18) -> 58500
B20: (*) Coste de instrumentos de gestión (valoración de puestos, riesgos psicosociales, plan de formación) que el
B21: Ayuntamiento debe dotar de perspectiva de género con independencia de este plan. No es gasto propio del plan.
B23: PRESUPUESTO POR CAPÍTULO (4 años)
B24: Capítulo | C24: Presupuesto externo
B25: 1. Sistema de gestión de personas | C25: =SUMIFS('Datos (aux)'!L2:L61,'Datos (aux)'!$P$2:$P$61,1)+SUMIFS('Datos (aux)'!M2:M61,'Datos (aux)'!$P$2:$P$61,1)+SUMIFS('Datos (aux)'!N2:N61,'Datos (aux)'!$P$2:$P$61,1)+SUMIFS('Datos (aux)'!O2:O61,'Datos (aux)'!$P$2:$P$61,1) -> 0
B26: 2. Acceso, selección y promoción | C26: =SUMIFS('Datos (aux)'!L2:L61,'Datos (aux)'!$P$2:$P$61,2)+SUMIFS('Datos (aux)'!M2:M61,'Datos (aux)'!$P$2:$P$61,2)+SUMIFS('Datos (aux)'!N2:N61,'Datos (aux)'!$P$2:$P$61,2)+SUMIFS('Datos (aux)'!O2:O61,'Datos (aux)'!$P$2:$P$61,2) -> 0
B27: 3. Formación | C27: =SUMIFS('Datos (aux)'!L2:L61,'Datos (aux)'!$P$2:$P$61,3)+SUMIFS('Datos (aux)'!M2:M61,'Datos (aux)'!$P$2:$P$61,3)+SUMIFS('Datos (aux)'!N2:N61,'Datos (aux)'!$P$2:$P$61,3)+SUMIFS('Datos (aux)'!O2:O61,'Datos (aux)'!$P$2:$P$61,3) -> 8000
B28: 4. Seguridad y salud laboral | C28: =SUMIFS('Datos (aux)'!L2:L61,'Datos (aux)'!$P$2:$P$61,4)+SUMIFS('Datos (aux)'!M2:M61,'Datos (aux)'!$P$2:$P$61,4)+SUMIFS('Datos (aux)'!N2:N61,'Datos (aux)'!$P$2:$P$61,4)+SUMIFS('Datos (aux)'!O2:O61,'Datos (aux)'!$P$2:$P$61,4) -> 15000
B29: 5. Valoración y auditoría retributiva | C29: =SUMIFS('Datos (aux)'!L2:L61,'Datos (aux)'!$P$2:$P$61,5)+SUMIFS('Datos (aux)'!M2:M61,'Datos (aux)'!$P$2:$P$61,5)+SUMIFS('Datos (aux)'!N2:N61,'Datos (aux)'!$P$2:$P$61,5)+SUMIFS('Datos (aux)'!O2:O61,'Datos (aux)'!$P$2:$P$61,5) -> 11000
B30: 6. Conciliación corresponsable | C30: =SUMIFS('Datos (aux)'!L2:L61,'Datos (aux)'!$P$2:$P$61,6)+SUMIFS('Datos (aux)'!M2:M61,'Datos (aux)'!$P$2:$P$61,6)+SUMIFS('Datos (aux)'!N2:N61,'Datos (aux)'!$P$2:$P$61,6)+SUMIFS('Datos (aux)'!O2:O61,'Datos (aux)'!$P$2:$P$61,6) -> 0
B31: 7. Cultura organizacional | C31: =SUMIFS('Datos (aux)'!L2:L61,'Datos (aux)'!$P$2:$P$61,7)+SUMIFS('Datos (aux)'!M2:M61,'Datos (aux)'!$P$2:$P$61,7)+SUMIFS('Datos (aux)'!N2:N61,'Datos (aux)'!$P$2:$P$61,7)+SUMIFS('Datos (aux)'!O2:O61,'Datos (aux)'!$P$2:$P$61,7) -> 24500
B32: 8. Violencia y acoso | C32: =SUMIFS('Datos (aux)'!L2:L61,'Datos (aux)'!$P$2:$P$61,8)+SUMIFS('Datos (aux)'!M2:M61,'Datos (aux)'!$P$2:$P$61,8)+SUMIFS('Datos (aux)'!N2:N61,'Datos (aux)'!$P$2:$P$61,8)+SUMIFS('Datos (aux)'!O2:O61,'Datos (aux)'!$P$2:$P$61,8) -> 0
B33: TOTAL | C33: =SUM(C25:C32) -> 58500

Sheet Plan operativo
A1: Cód. | B1: Capítulo / Eje | C1: Objetivo | D1: Acción | E1: Descripción | F1: Indicador | G1: Persona responsable | H1: Tipo | I1: Años | J1: Horas gestión responsable | K1: Rol apoyo | L1: Horas apoyo | M1: ¿Externaliza? | N1: Tipo de presupuesto | O1: Presupuesto externo (€)
A2: 1.1.1 | B2: 1. Sistema de gestión de personas | C2: Constituir la estructura de gestión del plan | D2: 1.1.1 Aprobar, registrar y difundir el plan | E2: Aprobación del I Plan de Igualdad en el Empleo Público en los órganos competentes, negociación con la representación sindical, inscripción en el Registro de planes de igualdad de las Administraciones Públicas y difusión a toda la plantilla por los canales internos, incluidos los que alcanzan al personal sin acceso habitual a medios informáticos | F2: Documento aprobado | G2: Persona responsable de la gestión del plan, dependiente de Secretaría | H2: Puntual | I2: 2027 | J2: 16 | K2: Secretaría | L2: 4 | M2: No | O2: 0
A3: 1.1.2 | B3: 1. Sistema de gestión de personas | C3: Constituir la estructura de gestión del plan | D3: 1.1.2 Designar la persona responsable de la gestión del plan, dependiente de Secretaría | E3: Designación formal, con funciones y dedicación establecidas por escrito. Se prevé que pueda realizarse mediante la contratación de una persona a través del plan de empleo. | F3: Persona designada | G3: Persona responsable de la gestión del plan, dependiente de Secretaría | H3: Puntual | I3: 2027 | J3: 6 | K3: Alcaldía | L3: 2 | M3: No | O3: 0
A4: 1.1.3 | B4: 1. Sistema de gestión de personas | C4: Constituir la estructura de gestión del plan | D4: 1.1.3 Constituir el grupo motor técnico y mantenerlo operativo | E4: Integrado por la Secretaría, la persona responsable de la gestión del plan, dependiente de Secretaría y la persona responsable de las políticas de igualdad municipales, con el liderazgo de la primera. En este espacio se definen las funciones que corresponden a la responsable de las políticas de igualdad municipales respecto del plan interno. Incluye la convocatoria de las reuniones, su celebración, el levantamiento de actas y el seguimiento de los acuerdos | F4: Órgano constituido y actas | G4: Persona responsable de la gestión del plan, dependiente de Secretaría | H4: Continua | I4: Todos los años | J4: 32 | K4: Técnica igualdad | L4: 10 | M4: No | O4: 0
A5: 1.1.4 | B5: 1. Sistema de gestión de personas | C5: Constituir la estructura de gestión del plan | D5: 1.1.4 Constituir la Comisión de Igualdad y mantenerla operativa | E5: Órgano paritario con representación de la organización y representación sindical, articulado con la mesa de negociación, con composición, funciones y periodicidad definidas. Incluye convocatoria, celebración, actas y seguimiento de acuerdos | F5: Órgano constituido y actas | G5: Persona responsable de la gestión del plan, dependiente de Secretaría | H5: Continua | I5: Todos los años | J5: 28 | K5: Comisión de Igualdad | L5: 8 | M5: No | O5: 0
A6: 1.1.5 | B6: 1. Sistema de gestión de personas | C6: Constituir la estructura de gestión del plan | D6: 1.1.5 Constituir el grupo motor político y mantenerlo operativo | E6: Espacio de seguimiento entre la Alcaldía, responsable de personal, y la Concejalía de Igualdad. Incluye la convocatoria anual, la celebración de la reunión, el acta y el seguimiento de los compromisos adquiridos | F6: Órgano constituido y actas | G6: Persona responsable de la gestión del plan, dependiente de Secretaría | H6: Continua | I6: Todos los años | J6: 20 | K6: Alcaldía | L6: 6 | M6: No | O6: 0
A7: 1.2.1 | B7: 1. Sistema de gestión de personas | C7: Planificar, hacer seguimiento y evaluar | D7: 1.2.1 Elaborar y aprobar un plan operativo anual | E7: Cada año, en el primer trimestre, con las medidas que se ejecutan en el ejercicio, los servicios implicados, el calendario, las horas de dedicación y el presupuesto necesario, aprobado por las estructuras de gestión del plan. Su diseño ha de ser sencillo y sostenible con los medios disponibles | F7: Documento aprobado | G7: Persona responsable de la gestión del plan, dependiente de Secretaría | H7: Continua | I7: Todos los años | J7: 32 | K7: — | L7: 0 | M7: No | O7: 0
A8: 1.2.2 | B8: 1. Sistema de gestión de personas | C8: Planificar, hacer seguimiento y evaluar | D8: 1.2.2 Elaborar un informe anual de seguimiento y evaluación | E8: Con los indicadores desagregados por sexo, el grado de ejecución de las medidas, las dificultades encontradas y las propuestas de ajuste, presentado a la Comisión de Igualdad | F8: Documento elaborado | G8: Persona responsable de la gestión del plan, dependiente de Secretaría | H8: Continua | I8: Todos los años | J8: 80 | K8: — | L8: 0 | M8: No | O8: 0
A9: 1.2.3 | B9: 1. Sistema de gestión de personas | C9: Planificar, hacer seguimiento y evaluar | D9: 1.2.3 Devolver anualmente los resultados a la plantilla | E9: Resumen breve de lo ejecutado y lo pendiente, en formatos que lleguen a todo el personal, por medios presenciales o telemáticos según se considere oportuno en cada caso | F9: Acción ejecutada | G9: Persona responsable de la gestión del plan, dependiente de Secretaría | H9: Continua | I9: Todos los años | J9: 16 | K9: — | L9: 0 | M9: No | O9: 0
A10: 1.3.1 | B10: 1. Sistema de gestión de personas | C10: Disponer de datos desagregados por sexo | D10: 1.3.1 Extender la explotación de los datos desagregados por sexo a los registros de gestión de personas | E10: Selección, promoción, formación, permisos y medidas de conciliación, retribuciones y bajas. Incluye determinar qué informes permite extraer la herramienta de nóminas y dejar configurados los que el plan necesita para su seguimiento y para la aplicación de la cláusula de prioridad prevista en el artículo 21 del Decreto Legislativo 1/2023 | F10: Registro actualizado | G10: Persona responsable de la gestión del plan, dependiente de Secretaría | H10: Puntual | I10: 2028 | J10: 28 | K10: Secretaría | L10: 12 | M10: No | O10: 0
A11: 2.1.1 | B11: 2. Acceso, selección y promoción | C11: Incorporar las garantías de igualdad a todas las vías de acceso | D11: 2.1.1 Elaborar un modelo único de bases con las cláusulas de igualdad | E11: Modelo aplicable a todos los procesos selectivos, con las obligaciones de los artículos 18.5, 19.4 y 21 del Decreto Legislativo 1/2023: cláusula de prioridad en favor de las mujeres formulada conforme al texto legal, composición equilibrada del tribunal, valoración del tiempo dedicado a cuidados, protección de la maternidad, adaptación de las pruebas en situaciones de embarazo, parto y lactancia, contenidos de igualdad en los temarios y uso no sexista del lenguaje | F11: Documento elaborado | G11: Persona responsable de la gestión del plan, dependiente de Secretaría | H11: Puntual | I11: 2027 | J11: 12 | K11: Secretaría | L11: 8 | M11: No | O11: 0
A12: 2.1.2 | B12: 2. Acceso, selección y promoción | C12: Incorporar las garantías de igualdad a todas las vías de acceso | D12: 2.1.2 Modificar el Reglamento de bolsas de trabajo | E12: Incorporación de las mismas garantías a la vía de acceso del personal laboral e interino, con negociación en la mesa correspondiente | F12: Instrumento revisado | G12: Persona responsable de la gestión del plan, dependiente de Secretaría | H12: Puntual | I12: 2028 | J12: 20 | K12: Secretaría | L12: 10 | M12: No | O12: 0
A13: 2.1.3 | B13: 2. Acceso, selección y promoción | C13: Incorporar las garantías de igualdad a todas las vías de acceso | D13: 2.1.3 Aplicar una lista de verificación previa a cada convocatoria | E13: Instrumento breve de comprobación del lenguaje empleado y de los requisitos y formulaciones que puedan operar como barrera para uno de los sexos, aplicado antes de dar por válida la convocatoria. La medida recoge una propuesta formulada por la representación de personal | F13: Cláusula/criterio incorporado | G13: Persona responsable de la gestión del plan, dependiente de Secretaría | H13: Puntual | I13: 2028 | J13: 12 | K13: — | L13: 0 | M13: No | O13: 0
... A19: 2.4.4 | B19: 2. Acceso, selección y promoción | C19: Actuar sobre la segregación en el acceso | D19: 2.4.4 Planificar el relevo generacional con perspectiva de género | E19: Previsión de las vacantes derivadas de jubilaciones durante la vigencia del plan, con determinación de la composición por sexo de cada puesto afectado y de las medidas aplicables en su cobertura | F19: Acción ejecutada | G19: Persona responsable de la gestión del plan, dependiente de Secretaría | H19: Puntual | I19: 2030 | J19: 32 | K19: Secretaría | L19: 10 | M19: No | O19: 0
A20: 3.1.1 | B20: 3. Formación | C20: Capacitar en igualdad a quienes gestionan personas | D20: 3.1.1 Formar al personal de gestión de personas en selección sin sesgos | E20: Acción formativa (8 h) sobre igualdad en la selección y las convocatorias sin sesgos, dirigida al personal con funciones de gestión de personas (Secretaría, Intervención, RR. HH.). | F20: Nº de sesiones y asistentes por sexo | G20: Persona responsable de la gestión del plan, dependiente de Secretaría | H20: Puntual | I20: 2027 | J20: 12 | K20: — | L20: 0 | M20: Sí | N20: Propio del plan | O20: 1200
A21: 3.1.2 | B21: 3. Formación | C21: Capacitar en igualdad a quienes gestionan personas | D21: 3.1.2 Formar a la Comisión de Igualdad y al grupo motor | E21: Acción formativa de arranque (6 h) sobre el funcionamiento del plan de igualdad, el seguimiento y el papel de la Comisión, dirigida a la Comisión de Igualdad y al grupo motor, al constituirse. | F21: Nº de sesiones y asistentes por sexo | G21: Persona responsable de la gestión del plan, dependiente de Secretaría | H21: Puntual | I21: 2028 | J21: 10 | K21: — | L21: 0 | M21: Sí | N21: Propio del plan | O21: 900
A22: 3.1.3 | B22: 3. Formación | C22: Capacitar en igualdad a quienes gestionan personas | D22: 3.1.3 Formar al personal de gestión de personas en valoración y retribución | E22: Acción formativa (8 h) sobre valoración de puestos y retribución con perspectiva de género, dirigida al personal con funciones de gestión de personas. | F22: Nº de sesiones y asistentes por sexo | G22: Persona responsable de la gestión del plan, dependiente de Secretaría | H22: Puntual | I22: 2027 | J22: 12 | K22: — | L22: 0 | M22: Sí | N22: Propio del plan | O22: 1200
A23: 3.2.1 | B23: 3. Formación | C23: Dotarse de un plan de formación con perspectiva de género | D23: 3.2.1 Elaborar un plan de formación con perspectiva de género que incluya la formación en igualdad | E23: Elaborar un plan de formación del personal del que el Ayuntamiento carece, incorporando desde su origen la perspectiva de género y recogiendo las acciones formativas en igualdad. Puede subcontratarse su elaboración. | F23: Documento elaborado | G23: Persona responsable de la gestión del plan, dependiente de Secretaría | H23: Puntual | I23: 2027 | J23: 24 | K23: — | L23: 0 | M23: Sí | N23: Instrumento global | O23: 3500
A24: 3.2.2 | B24: 3. Formación | C24: Dotarse de un plan de formación con perspectiva de género | D24: 3.2.2 Concretar y aprobar la programación formativa anual | E24: Concretar y aprobar cada año la programación formativa, dentro del plan de formación, garantizando que mantiene la perspectiva de género y ejecuta las acciones formativas en igualdad previstas. | F24: Documento aprobado | G24: Persona responsable de la gestión del plan, dependiente de Secretaría | H24: Continua | I24: Todos los años | J24: 28 | K24: — | L24: 0 | M24: No | O24: 0
A25: 3.2.3 | B25: 3. Formación | C25: Dotarse de un plan de formación con perspectiva de género | D25: 3.2.3 Incorporar la perspectiva de género a la formación propia | E25: Valoración previa de su pertinencia en cada acción formativa que el Ayuntamiento organice y, cuando proceda, inclusión de contenidos específicos en el temario | F25: Nº de sesiones y asistentes por sexo | G25: Persona responsable de la gestión del plan, dependiente de Secretaría | H25: Continua | I25: Todos los años | J25: 20 | K25: — | L25: 0 | M25: No | O25: 0
A26: 3.3.1 | B26: 3. Formación | C26: Llevar la formación a los puestos que hoy no la reciben | D26: 3.3.1 Adaptar horarios y modalidades | E26: Programación de las acciones formativas en franjas compatibles con la jornada del servicio de limpieza y con la turnicidad de la Policía Local, computando las horas como tiempo de trabajo | F26: Acción ejecutada | G26: Persona responsable de la gestión del plan, dependiente de Secretaría | H26: Continua | I26: Todos los años | J26: 12 | K26: — | L26: 0 | M26: No | O26: 0
A27: 3.3.2 | B27: 3. Formación | C27: Llevar la formación a los puestos que hoy no la reciben | D27: 3.3.2 Establecer un canal de comunicación para el personal sin acceso informático | E27: Vía estable de comunicación de la oferta formativa para la Brigada de Obras, el servicio de limpieza y la conserjería, que no dependa del correo electrónico | F27: Nº de sesiones y asistentes por sexo | G27: Persona responsable de la gestión del plan, dependiente de Secretaría | H27: Puntual | I27: 2029 | J27: 10 | K27: — | L27: 0 | M27: No | O27: 0
A28: 3.3.3 | B28: 3. Formación | C28: Llevar la formación a los puestos que hoy no la reciben | D28: 3.3.3 Formar a los puestos operativos y de limpieza en su puesto de trabajo con perspectiva de género | E28: Acción formativa (8 h) sobre el propio puesto de trabajo con perspectiva de género, en formato accesible, dirigida al personal operativo y de limpieza, el colectivo con menor acceso a la formación según el diagnóstico. | F28: Nº de sesiones y asistentes por sexo | G28: Persona responsable de la gestión del plan, dependiente de Secretaría | H28: Puntual | I28: 2028 | J28: 12 | K28: — | L28: 0 | M28: Sí | N28: Propio del plan | O28: 1200
A29: 3.4.1 | B29: 3. Formación | C29: Registrar y evaluar la participación | D29: 3.4.1 Registrar la participación en formación desagregada por sexo | E29: Registro por sexo, puesto, grupo profesional y acción formativa, en las condiciones exigidas para la homologación, con explotación anual de los datos | F29: Nº de sesiones y asistentes por sexo | G29: Persona responsable de la gestión del plan, dependiente de Secretaría | H29: Continua | I29: Todos los años | J29: 12 | K29: — | L29: 0 | M29: No | O29: 0
A30: 4.1.1 | B30: 4. Seguridad y salud laboral | C30: Incorporar la perspectiva de género al sistema preventivo | D30: 4.1.1 Realizar la evaluación de riesgos psicosociales con perspectiva de género | E30: Retomar, a través del servicio de prevención, la evaluación iniciada y no concluida, incorporando la doble presencia y la exposición sostenida a la hostilidad de la ciudadanía entre los factores de análisis, con participación de la plantilla y resultados desagregados por sexo. Constituye la prioridad del capítulo por su exigibilidad conforme al artículo 47.5, y conecta con el protocolo de actuación frente al acoso. | F30: Estudio realizado | G30: Persona responsable de la gestión del plan, dependiente de Secretaría | H30: Puntual | I30: 2027 | J30: 80 | K30: Servicio de prevención | L30: 16 | M30: Sí | N30: Instrumento global | O30: 12000
A31: 4.1.2 | B31: 4. Seguridad y salud laboral | C31: Incorporar la perspectiva de género al sistema preventivo | D31: 4.1.2 Incorporar la variable sexo y los riesgos de los servicios feminizados a la evaluación de riesgos | E31: En la próxima revisión de la evaluación de riesgos, aplicar las herramientas de Osalan para examinar las tareas efectivamente realizadas en la atención a la ciudadanía y en la limpieza —exposición a hostilidad, a productos químicos y carga física—, generar informes desagregados por sexo y revisar que los equipos de protección individual se adecuen a la diversidad morfológica. | F31: Estudio realizado | G31: Persona responsable de la gestión del plan, dependiente de Secretaría | H31: Puntual | I31: 2027 | J31: 28 | K31: Servicio de prevención | L31: 40 | M31: No | O31: 0
A32: 4.1.3 | B32: 4. Seguridad y salud laboral | C32: Incorporar la perspectiva de género al sistema preventivo | D32: 4.1.3 Rehacer el plan de prevención incorporando la perspectiva de género | E32: Rehacer el plan de prevención de riesgos laborales del Ayuntamiento incorporando en él la perspectiva de género en su objeto, su metodología y sus medidas. El servicio de prevención realiza la mayor parte del trabajo técnico. | F32: Cláusula/criterio incorporado | G32: Persona responsable de la gestión del plan, dependiente de Secretaría | H32: Puntual | I32: 2028 | J32: 20 | K32: Servicio de prevención | L32: 100 | M32: No | O32: 0
A33: 4.1.4 | B33: 4. Seguridad y salud laboral | C33: Incorporar la perspectiva de género al sistema preventivo | D33: 4.1.4 Formar cada año en un aspecto de seguridad y salud laboral con perspectiva de género | E33: Impartir cada año una acción formativa (4 h) sobre un aspecto de la seguridad y la salud laboral con perspectiva de género, dirigida a la plantilla: en 2027 riesgos psicosociales; en 2028 ergonomía; en 2029 teletrabajo y desconexión digital; y en 2030 violencia de terceros y usuarios, especialmente relevante en los servicios de atención feminizados. | F33: Nº de sesiones y asistentes por sexo | G33: Persona responsable de la gestión del plan, dependiente de Secretaría | H33: Continua | I33: Todos los años | J33: 10 | K33: — | L33: 0 | M33: Sí | N33: Propio del plan | O33: 600
A34: 4.2.1 | B34: 4. Seguridad y salud laboral | C34: Asegurar la perspectiva de género en la contratación del servicio de prevención | D34: 4.2.1 Introducir cláusulas de igualdad en la contratación del servicio de prevención y verificar su cumplimiento | E34: En la próxima licitación del servicio de prevención ajeno, incorporar la igualdad en el objeto del contrato y las cláusulas del artículo 22 del Decreto Legislativo 1/2023, extenderlas expresamente a la evaluación de riesgos psicosociales, exigir formación específica en igualdad al equipo adjudicatario y verificar el cumplimiento de esas cláusulas durante toda la prestación. | F34: Cláusula/criterio incorporado | G34: Persona responsable de la gestión del plan, dependiente de Secretaría | H34: Puntual | I34: 2029 | J34: 16 | K34: Secretaría | L34: 8 | M34: No | O34: 0
A35: 4.3.1 | B35: 4. Seguridad y salud laboral | C35: Reforzar la participación y la comunicación en materia preventiva | D35: 4.3.1 Constituir el Comité de Seguridad y Salud e incorporarlo a la planificación de las acciones | E35: Constituir el Comité de Seguridad y Salud, formar en igualdad a las personas que lo integren y contar con él en la planificación y el seguimiento de las acciones del plan en materia de seguridad y salud laboral. | F35: Nº de sesiones y asistentes por sexo | G35: Persona responsable de la gestión del plan, dependiente de Secretaría | H35: Puntual | I35: 2028 | J35: 10 | K35: Secretaría | L35: 4 | M35: Sí | N35: Propio del plan | O35: 600
A36: 4.3.2 | B36: 4. Seguridad y salud laboral | C36: Reforzar la participación y la comunicación en materia preventiva | D36: 4.3.2 Garantizar que la información preventiva alcance a toda la plantilla | E36: Habilitar un canal que llegue a los servicios sin correo corporativo —Brigada de Obras y limpieza—, en coherencia con la medida sobre canales de comunicación del capítulo 3. | F36: Nº de sesiones y asistentes por sexo | G36: Persona responsable de la gestión del plan, dependiente de Secretaría | H36: Continua | I36: Todos los años | J36: 10 | K36: — | L36: 0 | M36: No | O36: 0
A37: 5.1.1 | B37: 5. Valoración y auditoría retributiva | C37: Incorporar la perspectiva de género a la valoración de puestos en curso | D37: 5.1.1 Solicitar a la empresa adjudicataria la corrección del proyecto de valoración | E37: Requerir a la empresa que realiza la valoración que incorpore la perspectiva de género al proyecto en curso, añadiendo el esfuerzo emocional, la responsabilidad sobre el bienestar, las habilidades de cuidado y la resolución de conflictos como factores con grado y peso propios, tomando como referencia la herramienta de trabajo de igual valor del Ministerio de Igualdad. En futuras contrataciones relacionadas con la valoración, la perspectiva de género y la formación específica en igualdad del equipo se incluirán en el objeto del contrato. | F37: Acción ejecutada | G37: Persona responsable de la gestión del plan, dependiente de Secretaría | H37: Puntual | I37: 2027 | J37: 28 | K37: Secretaría | L37: 16 | M37: Sí | N37: Instrumento global | O37: 6000
A38: 5.1.2 | B38: 5. Valoración y auditoría retributiva | C38: Incorporar la perspectiva de género a la valoración de puestos en curso | D38: 5.1.2 Condicionar la valoración a la previa evaluación de riesgos psicosociales | E38: Realizar la evaluación de riesgos psicosociales prevista en el capítulo 4 antes de completar la valoración, de modo que la carga emocional y psicosocial de cada puesto se valore sobre datos objetivos. | F38: Estudio realizado | G38: Persona responsable de la gestión del plan, dependiente de Secretaría | H38: Puntual | I38: 2027 | J38: 12 | K38: — | L38: 0 | M38: No | O38: 0
A39: 5.1.3 | B39: 5. Valoración y auditoría retributiva | C39: Incorporar la perspectiva de género a la valoración de puestos en curso | D39: 5.1.3 Garantizar la participación informada de las mujeres en la negociación de la valoración | E39: Asegurar que las mujeres de la plantilla reciben información sobre el proceso de valoración y participan en la toma de decisiones y en su aceptación, más allá de la composición de la representación sindical, articulando para ello cauces específicos de consulta y participación. | F39: Nº de sesiones y asistentes por sexo | G39: Persona responsable de la gestión del plan, dependiente de Secretaría | H39: Puntual | I39: 2028 | J39: 20 | K39: Técnica igualdad | L39: 8 | M39: No | O39: 0
A40: 5.2.1 | B40: 5. Valoración y auditoría retributiva | C40: Dotar a la función de igualdad de un puesto propio | D40: 5.2.1 Crear la plaza de personal técnico de igualdad en la RPT | E40: Crear en la relación de puestos de trabajo una plaza de personal técnico de igualdad con dedicación y formación específicas. | F40: Plaza creada en RPT | G40: Persona responsable de la gestión del plan, dependiente de Secretaría | H40: Puntual | I40: 2029 | J40: 28 | K40: Secretaría | L40: 12 | M40: No | O40: 0
A41: 5.2.2 | B41: 5. Valoración y auditoría retributiva | C41: Dotar a la función de igualdad de un puesto propio | D41: 5.2.2 Adscribir la unidad de igualdad a la Alcaldía | E41: Adscribir la unidad de igualdad a la Alcaldía, garantizando su dependencia directa y su capacidad de impulso transversal. | F41: Adscripción formalizada | G41: Persona responsable de la gestión del plan, dependiente de Secretaría | H41: Puntual | I41: 2029 | J41: 10 | K41: Alcaldía | L41: 4 | M41: No | O41: 0
A42: 5.3.1 | B42: 5. Valoración y auditoría retributiva | C42: Establecer un sistema estable de igualdad y transparencia retributiva | D42: 5.3.1 Realizar la auditoría retributiva y actualizar el registro | E42: Completar la auditoría retributiva una vez revisada la valoración de puestos con perspectiva de género, y actualizar anualmente el registro retributivo analizando las diferencias por sexo, grupo y concepto en cada nivel, sin limitar el análisis a la cifra global, y poniendo la información a disposición de la Comisión de Igualdad. | F42: Registro actualizado | G42: Persona responsable de la gestión del plan, dependiente de Secretaría | H42: Puntual | I42: 2029 | J42: 32 | K42: Secretaría/Intervención | L42: 16 | M42: Sí | N42: Instrumento global | O42: 5000
A43: 5.3.2 | B43: 5. Valoración y auditoría retributiva | C43: Establecer un sistema estable de igualdad y transparencia retributiva | D43: 5.3.2 Desarrollar una política de transparencia retributiva | E43: Celebrar una reunión anual de información a la plantilla sobre la política retributiva y los resultados del análisis de brecha, asegurando la presencia y la participación de las mujeres, con una comunicación global de los resultados accesible al conjunto del personal. | F43: Acción ejecutada | G43: Persona responsable de la gestión del plan, dependiente de Secretaría | H43: Continua | I43: Todos los años | J43: 16 | K43: — | L43: 0 | M43: No | O43: 0
A44: 6.1.1 | B44: 6. Conciliación corresponsable | C44: Promover un uso corresponsable de las medidas de conciliación | D44: 6.1.1 Difundir un catálogo de medidas de conciliación | E44: Elaborar y difundir un catálogo accesible que explique las medidas disponibles, las mejoras internas y el procedimiento de solicitud, e incluirlo en el protocolo de acogida del personal de nueva incorporación. | F44: Acción de difusión realizada | G44: Persona responsable de la gestión del plan, dependiente de Secretaría | H44: Puntual | I44: 2029 | J44: 16 | K44: — | L44: 0 | M44: No | O44: 0
A45: 6.1.2 | B45: 6. Conciliación corresponsable | C45: Promover un uso corresponsable de las medidas de conciliación | D45: 6.1.2 Sensibilizar en corresponsabilidad, con atención a los hombres | E45: Acción formativa y de sensibilización (4 h) sobre corresponsabilidad y uso de las medidas de conciliación, dirigida a la plantilla y con especial atención a los hombres. Puede impartirla el programa Gizonduz de Emakunde de forma gratuita. | F45: Nº de sesiones y asistentes por sexo | G45: Persona responsable de la gestión del plan, dependiente de Secretaría | H45: Puntual | I45: 2028 | J45: 12 | K45: — | L45: 0 | M45: No | O45: 0
...

Sheet Datos (aux)
A1: Cód. | B1: TipoPpto | C1: Ext | D1: H_resp_2027 | E1: H_resp_2028 | F1: H_resp_2029 | G1: H_resp_2030 | H1: H_apoyo_2027 | I1: H_apoyo_2028 | J1: H_apoyo_2029 | K1: H_apoyo_2030 | L1: Ppto_2027 | M1: Ppto_2028 | N1: Ppto_2029 | O1: Ppto_2030 | P1: Cap
A2: 1.1.1 | B2: - | C2: No | D2: 16 | E2: 0 | F2: 0 | G2: 0 | H2: 4 | I2: 0 | J2: 0 | K2: 0 | L2: 0 | M2: 0 | N2: 0 | O2: 0 | P2: 1
A3: 1.1.2 | B3: - | C3: No | D3: 6 | E3: 0 | F3: 0 | G3: 0 | H3: 2 | I3: 0 | J3: 0 | K3: 0 | L3: 0 | M3: 0 | N3: 0 | O3: 0 | P3: 1
A4: 1.1.3 | B4: - | C4: No | D4: 32 | E4: 32 | F4: 32 | G4: 32 | H4: 10 | I4: 10 | J4: 10 | K4: 10 | L4: 0 | M4: 0 | N4: 0 | O4: 0 | P4: 1
A5: 1.1.4 | B5: - | C5: No | D5: 28 | E5: 28 | F5: 28 | G5: 28 | H5: 8 | I5: 8 | J5: 8 | K5: 8 | L5: 0 | M5: 0 | N5: 0 | O5: 0 | P5: 1
A6: 1.1.5 | B6: - | C6: No | D6: 20 | E6: 20 | F6: 20 | G6: 20 | H6: 6 | I6: 6 | J6: 6 | K6: 6 | L6: 0 | M6: 0 | N6: 0 | O6: 0 | P6: 1
A7: 1.2.1 | B7: - | C7: No | D7: 32 | E7: 32 | F7: 32 | G7: 32 | H7: 0 | I7: 0 | J7: 0 | K7: 0 | L7: 0 | M7: 0 | N7: 0 | O7: 0 | P7: 1
A8: 1.2.2 | B8: - | C8: No | D8: 80 | E8: 80 | F8: 80 | G8: 80 | H8: 0 | I8: 0 | J8: 0 | K8: 0 | L8: 0 | M8: 0 | N8: 0 | O8: 0 | P8: 1
A9: 1.2.3 | B9: - | C9: No | D9: 16 | E9: 16 | F9: 16 | G9: 16 | H9: 0 | I9: 0 | J9: 0 | K9: 0 | L9: 0 | M9: 0 | N9: 0 | O9: 0 | P9: 1
A10: 1.3.1 | B10: - | C10: No | D10: 0 | E10: 28 | F10: 0 | G10: 0 | H10: 0 | I10: 12 | J10: 0 | K10: 0 | L10: 0 | M10: 0 | N10: 0 | O10: 0 | P10: 1
A11: 2.1.1 | B11: - | C11: No | D11: 12 | E11: 0 | F11: 0 | G11: 0 | H11: 8 | I11: 0 | J11: 0 | K11: 0 | L11: 0 | M11: 0 | N11: 0 | O11: 0 | P11: 2
A12: 2.1.2 | B12: - | C12: No | D12: 0 | E12: 20 | F12: 0 | G12: 0 | H12: 0 | I12: 10 | J12: 0 | K12: 0 | L12: 0 | M12: 0 | N12: 0 | O12: 0 | P12: 2
A13: 2.1.3 | B13: - | C13: No | D13: 0 | E13: 12 | F13: 0 | G13: 0 | H13: 0 | I13: 0 | J13: 0 | K13: 0 | L13: 0 | M13: 0 | N13: 0 | O13: 0 | P13: 2
... A61: 8.3.2 | B61: - | C61: No | D61: 0 | E61: 0 | F61: 12 | G61: 0 | H61: 0 | I61: 0 | J61: 0 | K61: 0 | L61: 0 | M61: 0 | N61: 0 | O61: 0 | P61: 8

Sheet Seguimiento
A1: Seguimiento anual del Plan de Igualdad Interno · Ayuntamiento de Ortuella
A2: Rellenar cada año el bloque correspondiente. El Dashboard se actualiza automáticamente.
G3: SEGUIMIENTO 2027 | M3: SEGUIMIENTO 2028 | S3: SEGUIMIENTO 2029 | Y3: SEGUIMIENTO 2030
A4: Cód. | B4: Eje | C4: Acción | D4: Año previsto | E4: Horas prev. | F4: Ppto prev. (€) | G4: Estado | H4: Realizado (descripción) | I4: Documentos/resultados | J4: Horas ejec. | K4: Ppto ejec. (€) | L4: Observaciones | M4: Estado | N4: Realizado (descripción) | O4: Documentos/resultados | P4: Horas ejec. | Q4: Ppto ejec. (€) | R4: Observaciones | S4: Estado | T4: Realizado (descripción) | U4: Documentos/resultados | V4: Horas ejec. | W4: Ppto ejec. (€) | X4: Observaciones | Y4: Estado | Z4: Realizado (descripción) | AA4: Documentos/resultados | AB4: Horas ejec. | AC4: Ppto ejec. (€) | AD4: Observaciones
A5: ='Plan operativo'!A2 -> 1.1.1 | B5: 1 | C5: ='Plan operativo'!D2 -> 1.1.1 Aprobar, registrar y difundir el plan | D5: ='Plan operativo'!I2 -> 2027 | E5: ='Plan operativo'!J2 -> 16 | F5: ='Plan operativo'!O2 -> 0 | G5: Ejecutada | J5: 20 | K5: 500
A6: ='Plan operativo'!A3 -> 1.1.2 | B6: 1 | C6: ='Plan operativo'!D3 -> 1.1.2 Designar la persona responsable de la gestión del plan, dependiente de Secretaría | D6: ='Plan operativo'!I3 -> 2027 | E6: ='Plan operativo'!J3 -> 6 | F6: ='Plan operativo'!O3 -> 0 | G6: Ejecutada | J6: 20 | K6: 500
A7: ='Plan operativo'!A4 -> 1.1.3 | B7: 1 | C7: ='Plan operativo'!D4 -> 1.1.3 Constituir el grupo motor técnico y mantenerlo operativo | D7: ='Plan operativo'!I4 -> Todos los años | E7: ='Plan operativo'!J4 -> 32 | F7: ='Plan operativo'!O4 -> 0 | G7: Ejecutada | J7: 20 | K7: 500
A8: ='Plan operativo'!A5 -> 1.1.4 | B8: 1 | C8: ='Plan operativo'!D5 -> 1.1.4 Constituir la Comisión de Igualdad y mantenerla operativa | D8: ='Plan operativo'!I5 -> Todos los años | E8: ='Plan operativo'!J5 -> 28 | F8: ='Plan operativo'!O5 -> 0
A9: ='Plan operativo'!A6 -> 1.1.5 | B9: 1 | C9: ='Plan operativo'!D6 -> 1.1.5 Constituir el grupo motor político y mantenerlo operativo | D9: ='Plan operativo'!I6 -> Todos los años | E9: ='Plan operativo'!J6 -> 20 | F9: ='Plan operativo'!O6 -> 0
A10: ='Plan operativo'!A7 -> 1.2.1 | B10: 1 | C10: ='Plan operativo'!D7 -> 1.2.1 Elaborar y aprobar un plan operativo anual | D10: ='Plan operativo'!I7 -> Todos los años | E10: ='Plan operativo'!J7 -> 32 | F10: ='Plan operativo'!O7 -> 0
A11: ='Plan operativo'!A8 -> 1.2.2 | B11: 1 | C11: ='Plan operativo'!D8 -> 1.2.2 Elaborar un informe anual de seguimiento y evaluación | D11: ='Plan operativo'!I8 -> Todos los años | E11: ='Plan operativo'!J8 -> 80 | F11: ='Plan operativo'!O8 -> 0
A12: ='Plan operativo'!A9 -> 1.2.3 | B12: 1 | C12: ='Plan operativo'!D9 -> 1.2.3 Devolver anualmente los resultados a la plantilla | D12: ='Plan operativo'!I9 -> Todos los años | E12: ='Plan operativo'!J9 -> 16 | F12: ='Plan operativo'!O9 -> 0
A13: ='Plan operativo'!A10 -> 1.3.1 | B13: 1 | C13: ='Plan operativo'!D10 -> 1.3.1 Extender la explotación de los datos desagregados por sexo a los registros de gestión de personas | D13: ='Plan operativo'!I10 -> 2028 | E13: ='Plan operativo'!J10 -> 28 | F13: ='Plan operativo'!O10 -> 0
A14: ='Plan operativo'!A11 -> 2.1.1 | B14: 2 | C14: ='Plan operativo'!D11 -> 2.1.1 Elaborar un modelo único de bases con las cláusulas de igualdad | D14: ='Plan operativo'!I11 -> 2027 | E14: ='Plan operativo'!J11 -> 12 | F14: ='Plan operativo'!O11 -> 0
A15: ='Plan operativo'!A12 -> 2.1.2 | B15: 2 | C15: ='Plan operativo'!D12 -> 2.1.2 Modificar el Reglamento de bolsas de trabajo | D15: ='Plan operativo'!I12 -> 2028 | E15: ='Plan operativo'!J12 -> 20 | F15: ='Plan operativo'!O12 -> 0
A16: ='Plan operativo'!A13 -> 2.1.3 | B16: 2 | C16: ='Plan operativo'!D13 -> 2.1.3 Aplicar una lista de verificación previa a cada convocatoria | D16: ='Plan operativo'!I13 -> 2028 | E16: ='Plan operativo'!J13 -> 12 | F16: ='Plan operativo'!O13 -> 0
A17: ='Plan operativo'!A14 -> 2.2.1 | B17: 2 | C17: ='Plan operativo'!D14 -> 2.2.1 Someter cada convocatoria de oferta pública de empleo a evaluación previa de impacto en función del género | D17: ='Plan operativo'!I14 -> Todos los años | E17: ='Plan operativo'!J14 -> 16 | F17: ='Plan operativo'!O14 -> 0
A18: ='Plan operativo'!A15 -> 2.3.1 | B18: 2 | C18: ='Plan operativo'!D15 -> 2.3.1 Registrar la concurrencia y los resultados de cada proceso desagregados por sexo | D18: ='Plan operativo'!I15 -> Todos los años | E18: ='Plan operativo'!J15 -> 20 | F18: ='Plan operativo'!O15 -> 0
A19: ='Plan operativo'!A16 -> 2.4.1 | B19: 2 | C19: ='Plan operativo'!D16 -> 2.4.1 Verificar la aplicación del régimen específico en la Policía Local | D19: ='Plan operativo'!I16 -> 2029 | E19: ='Plan operativo'!J16 -> 16 | F19: ='Plan operativo'!O16 -> 0
... A64: ='Plan operativo'!A61 -> 8.3.2 | B64: 8 | C64: ='Plan operativo'!D61 -> 8.3.2 Elaborar y difundir una guía de recursos | D64: ='Plan operativo'!I61 -> 2029 | E64: ='Plan operativo'!J61 -> 12 | F64: ='Plan operativo'!O61 -> 0
